Workbook

Sheet Read me
A1: Translation master
A2: Every email in the project in English and in each translation, in one standard layout, with the results of the integrity checks.
A4: What each language covers
A5: Afrikaans: 117 emails (the Afrikaans batch). Translator and reviewer scores included.
A6: isiXhosa: the SAME 117 emails as Afrikaans, so Afrikaans and isiXhosa can be compared directly. The original isiXhosa batch of 120 emails was not translated.
A7: isiZulu: 120 emails (the isiZulu batch), translated in place in the original file. English restored from the batch file.
A8: isiNdebele: 120 emails (the isiNdebele batch). Only the bodies were translated; subjects are still English.
A9: Translator and reviewer scores exist only for Afrikaans, so kappa can only be calculated for Afrikaans.
A11: Sheets
A12: Summary: counts per language and issues per severity (formulas).
A13: Coverage: one row per email, showing which languages it was translated into.
A14: All records: one row per email per language (English included), in one layout.
... A19: Same email IDs as English; sender, receiver, date, label and urls unchanged; every link and email address in the body kept; body and subject actually translated; translation not much shorter than the English; translation belongs to the right email.

Sheet Summary
A1: Records per language
A2: Language | B2: Phishing | C2: Legitimate | D2: Total | E2: Fix before testing | F2: Check
A3: English | B3: =COUNTIFS('All records'!$B$2:$B$832,A3,'All records'!$E$2:$E$832,"phishing") -> 177 | C3: =COUNTIFS('All records'!$B$2:$B$832,A3,'All records'!$E$2:$E$832,"legitimate") -> 180 | D3: =B3+C3 -> 357 | E3: =COUNTIFS(Issues!$B$2:$B$26,A3,Issues!$A$2:$A$26,"Fix before testing") -> 0 | F3: =COUNTIFS(Issues!$B$2:$B$26,A3,Issues!$A$2:$A$26,"Check") -> 0
A4: Afrikaans | B4: =COUNTIFS('All records'!$B$2:$B$832,A4,'All records'!$E$2:$E$832,"phishing") -> 57 | C4: =COUNTIFS('All records'!$B$2:$B$832,A4,'All records'!$E$2:$E$832,"legitimate") -> 60 | D4: =B4+C4 -> 117 | E4: =COUNTIFS(Issues!$B$2:$B$26,A4,Issues!$A$2:$A$26,"Fix before testing") -> 0 | F4: =COUNTIFS(Issues!$B$2:$B$26,A4,Issues!$A$2:$A$26,"Check") -> 3
A5: isiXhosa | B5: =COUNTIFS('All records'!$B$2:$B$832,A5,'All records'!$E$2:$E$832,"phishing") -> 57 | C5: =COUNTIFS('All records'!$B$2:$B$832,A5,'All records'!$E$2:$E$832,"legitimate") -> 60 | D5: =B5+C5 -> 117 | E5: =COUNTIFS(Issues!$B$2:$B$26,A5,Issues!$A$2:$A$26,"Fix before testing") -> 0 | F5: =COUNTIFS(Issues!$B$2:$B$26,A5,Issues!$A$2:$A$26,"Check") -> 1
A6: isiZulu | B6: =COUNTIFS('All records'!$B$2:$B$832,A6,'All records'!$E$2:$E$832,"phishing") -> 60 | C6: =COUNTIFS('All records'!$B$2:$B$832,A6,'All records'!$E$2:$E$832,"legitimate") -> 60 | D6: =B6+C6 -> 120 | E6: =COUNTIFS(Issues!$B$2:$B$26,A6,Issues!$A$2:$A$26,"Fix before testing") -> 1 | F6: =COUNTIFS(Issues!$B$2:$B$26,A6,Issues!$A$2:$A$26,"Check") -> 9
A7: isiNdebele | B7: =COUNTIFS('All records'!$B$2:$B$832,A7,'All records'!$E$2:$E$832,"phishing") -> 60 | C7: =COUNTIFS('All records'!$B$2:$B$832,A7,'All records'!$E$2:$E$832,"legitimate") -> 60 | D7: =B7+C7 -> 120 | E7: =COUNTIFS(Issues!$B$2:$B$26,A7,Issues!$A$2:$A$26,"Fix before testing") -> 6 | F7: =COUNTIFS(Issues!$B$2:$B$26,A7,Issues!$A$2:$A$26,"Check") -> 2
A9: Emails translated into | B9: Count
A10: 1 language | B10: =COUNTIF(Coverage!$I$2:$I$358,1) -> 240
A11: 2 languages | B11: =COUNTIF(Coverage!$I$2:$I$358,2) -> 117
A13: Translation agreement (Afrikaans only) | B13: Value
A14: Cohen's kappa | B14: 0.08 | C14: Calculated with scikit-learn cohen_kappa_score on the Translator_score and Reviewer_score columns
A15: Exact agreement | B15: 0.54

Sheet All records
A1: email_id | B1: language | C1: version | D1: label | E1: label_name | F1: source_dataset | G1: sender | H1: receiver | I1: date | J1: subject | K1: body | L1: urls | M1: translator_score | N1: reviewer_score
A2: EMAIL_0001 | B2: English | C2: Original | D2: 0 | E2: legitimate | F2: SpamAssassin | G2: Conor Daly <conor.daly@oceanfree.net> | H2: social@linux.ie | I2: Wed, 07 Aug 2002 13:30:59 +0100 | J2: Re: [ILUG-Social] Anyone in Limerick want to help? | K2: Sorted. I've got someone... Thanks, Conor On Tue, Aug 06, 2002 at 03:29:38PM +0100 or so it is rumoured hereabouts, Conor Daly thought: > I've had an offer of a couple of secondhand 18" LCD monitors in Limerick. > Would anyone like to assist by going to test, purchase and store same for > a couple of weeks (I'm in dublin and going away for a bit so I won't be > able to organise collection for a while)? Please reply off-list of you > can help. -- Conor Daly <conor.daly@oceanfree.net> Domestic Sysadmin :-) --------------------- Faenor.cod.ie 1:32pm up 75 days, 22:50, 0 users, load average: 0.00, 0.00, 0.00 Hobbiton.cod.ie 1:30pm up 18 days, 19:54, 1 user, load average: 0.24, 0.12, 0.03 -- Irish Linux Users' Group Social Events: social@linux.ie http://www.linux.ie/mailman/listinfo/social for (un)subscription information. List maintainer: listmaster@linux.ie | L2: http://www.linux.ie/mailman/listinfo/social
A3: EMAIL_0001 | B3: Afrikaans | C3: Translation | D3: 0 | E3: legitimate | F3: SpamAssassin | G3: Conor Daly <conor.daly@oceanfree.net> | H3: social@linux.ie | I3: Wed, 07 Aug 2002 13:30:59 +0100 | J3: Re: [ILUG-Social] Iemand in Limerick wat wil help? | K3: Reggekry. Ek het iemand... Dankie, Conor Op Di, 06 Aug 2002 om 15:29:38 +0100, of so lui die gerugte hier rond, het Conor Daly gedink: > Ek het 'n aanbod gekry van 'n paar tweedehandse 18"-LCD-monitors in Limerick. > Sal iemand wil help deur te gaan toets, dit te koop en vir 'n paar weke > te stoor (ek is in Dublin en gaan 'n rukkie weg, so ek sal nie vir 'n > ruk afhaal kan reël nie)? Antwoord asseblief buite die lys as jy > kan help. -- Conor Daly <conor.daly@oceanfree.net> Huishoudelike stelseladministrateur :-) --------------------- Faenor.cod.ie 1:32pm up 75 days, 22:50, 0 users, load average: 0.00, 0.00, 0.00 Hobbiton.cod.ie 1:30pm up 18 days, 19:54, 1 user, load average: 0.24, 0.12, 0.03 -- Ierse Linux-gebruikersgroep se sosiale geleenthede: social@linux.ie http://www.linux.ie/mailman/listinfo/social vir inligting oor in- en uitskrywing. Lysbestuurder: listmaster@linux.ie | L3: http://www.linux.ie/mailman/listinfo/social | M3: 2 | N3: 2
A4: EMAIL_0001 | B4: isiXhosa | C4: Translation | D4: 0 | E4: legitimate | F4: SpamAssassin | G4: Conor Daly <conor.daly@oceanfree.net> | H4: social@linux.ie | I4: Wed, 07 Aug 2002 13:30:59 +0100 | J4: Ingaba ukhona umntu eLimerick ongathanda ukunceda? | K4: Ndiyifumene. Ndinomntu... Enkosi. Conor On Thu, 06 Aug 2002 ngo-15: 29: 38 + 0100, okanye ke amahemuhemu avela apha, uConor Daly wacinga: &gt; Ndifumene isibonelelo kwiimonitha eziyi-18"ze-LCD zaseLimerick. &gt; Ngaba ukhona umntu ongathanda ukunceda ngokuya kuvavanya, ukuyithenga nangeeveki ezimbalwa &gt; ukuyigcina (ndiseDublin ndize ndihambe okwethutyana, ngoko andizukuba &gt; jerk pick up ayikwazi ukulungiselela)? Nceda uphendule ngaphandle kwendlu ukuba wena &gt; ingakunceda. -- <conor.daly@oceanfree.net>Ikhaya LaseConor Daly umlawuli wenkqubo :-) --------------------- I-Faenor.cod.ie 1:32pm ukuya kutsho kwiintsuku eziyi-75, 22:50, 0 abasebenzisi, umyinge wokulayisha: 0.00, 0.00, 0.00 I-Hobbiton.cod.ie 1:30emva kwemini ukuya kutsho kwiintsuku eziyi-18, 19:54, umsebenzisi omnye, umyinge wokulayisha: 0.24, 0.12, 0.03 -- Imicimbi yentlalo yeqela lomsebenzisi weLinux waseIreland: social@linux.ie http://www.linux.ie/mailman/listinfo/social yolwazi lokungena nokuphuma. Umphathi Woluhlu: listmaster@linux.ie | L4: http://www.linux.ie/mailman/listinfo/social
A5: EMAIL_0005 | B5: English | C5: Original | D5: 0 | E5: legitimate | F5: SpamAssassin | G5: Fox <lds0062@cdc.net> | H5: razor-users@example.sourceforge.net | I5: Mon, 26 Aug 2002 16:14:04 -0400 | J5: [Razor-users] Preproc erasing message | K5: The following razor debugging sequence show my mail going from 9295 bytes to 0 bytes after the preproc runs, which gives me an exit code that is not 0. I included the message below. Fox Razor-Log: No /etc/razor/razor-agent.conf found, skipping. Razor-Log: No razor-agent.conf found, using defaults. Aug 26 10:28:09.225237 check[3469]: [ 1] [bootup] Logging initiated LogDebugLevel=9 to stdout Aug 26 10:28:09.225890 check[3469]: [ 5] computed razorhome=/etc/razor, conf=, ident=/etc/razor/identity Aug 26 10:28:09.226006 check[3469]: [ 2] Razor-Agents v2.14 starting razor-check -d -home=/etc/razor Aug 26 10:28:09.229704 check[3469]: [ 9] uname -a: Linux qmail.mckee.com 2.4.8-34.1mdk #1 Mon Nov 19 12:40:39 MST 2001 i686 unknown Aug 26 10:28:09.230155 check[3469]: [ 8] reading straight RFC822 mail from Aug 26 10:28:09.231524 check[3469]: [ 6] read 1 mail Aug 26 10:28:09.231923 check[3469]: [ 8] Client supported_engines: 1 2 3 4 Aug 26 10:28:09.233017 check[3469]: [ 8] prep_mail done: mail 1 headers=631, mime0=9295 Aug 26 10:28:09.233434 check[3469]: [ 6] skipping whitelist file (empty?): /etc/razor/razor-whitelist Aug 26 10:28:09.233995 check[3469]: [ 5] read_file: 1 items read from /etc/razor/servers.discovery.lst Aug 26 10:28:09.234369 check[3469]: [ 5] read_file: 1 items read from /etc/razor/servers.nomination.lst Aug 26 10:28:09.234697 check[3469]: [ 5] read_file: 3 items read from /etc/razor/servers.catalogue.lst Aug 26 10:28:09.235184 check[3469]: [ 9] Assigning defaults to honor.cloudmark.com Aug 26 10:28:09.235415 check[3469]: [ 9] Assigning defaults to truth.cloudmark.com Aug 26 10:28:09.235624 check[3469]: [ 9] Assigning defaults to fire.cloudmark.com Aug 26 10:28:09.235830 check[3469]: [ 9] Assigning defaults to apt.cloudmark.com Aug 26 10:28:09.236715 check[3469]: [ 5] read_file: 11 items read from /etc/razor/server.truth.cloudmark.com.conf Aug 26 10:28:09.237368 check[3469]: [ 5] read_file: 11 items read from /etc/razor/server.fire.cloudmark.com.conf Aug 26 10:28:09.237825 check[3469]: [ 5] 149643 seconds before closest server discovery Aug 26 10:28:09.238135 check[3469]: [ 6] truth.cloudmark.com is a Catalogue Server srl 51; computed min_cf=1, Server se: 0B Aug 26 10:28:09.238414 check[3469]: [ 8] Computed supported_engines: 1 2 4 Aug 26 10:28:09.238656 check[3469]: [ 8] Using next closest server truth.cloudmark.com:2703, cached info srl 51 Aug 26 10:28:09.238871 check[3469]: [ 8] mail 1 Subject: New Freeware Download Aug 26 10:28:09.290618 check[3469]: [ 6] preproc: mail 1.0 went from 9295 bytes to 0, erasing Aug 26 10:28:09.291100 check[3469]: [ 5] Connecting to truth.cloudmark.com ... Aug 26 10:28:09.505431 check[3469]: [ 8] Connection established Aug 26 10:28:09.505662 check[3469]: [ 4] truth.cloudmark.com >> 29 server greeting: sn=C&srl=51&ep4=7542-10&a=l Aug 26 10:28:09.506086 check[3469]: [ 6] truth.cloudmark.com is a Catalogue Server srl 51; computed min_cf=1, Server se: 0B Aug 26 10:28:09.506342 check[3469]: [ 8] Computed supported_engines: 1 2 4 Aug 26 10:28:09.506604 check[3469]: [ 8] mail 1.0 skipped in check Aug 26 10:28:09.506686 check[3469]: [ 5] No queries, no spam Aug 26 10:28:09.506787 check[3469]: [ 5] disconnecting from server truth.cloudmark.com Aug 26 10:28:09.507071 check[3469]: [ 4] truth.cloudmark.com << 5 Aug 26 10:28:09.507155 check[3469]: [ 6] a=q Aug 26 10:28:09.507959 check[3469]: [ 8] razor-check finished successfully. >>From bounce-html-sales1-21787251@lyris.execsoft.com Mon Aug 26 14:28:10 2002 Return-Path: <bounce-html-sales1-21787251@lyris.execsoft.com> Delivered-To: log@qmail.mckee.com Received: (qmail 3472 invoked from network); 26 Aug 2002 14:28:10 -0000 Received: from unknown (HELO port-216-3073879-ds200.devices.datareturn.net) (216.46.231.87) by 10.97.5.1 with SMTP; 26 Aug 2002 14:28:05 -0000 X-Mailer: Lyris Web Interface Date: Sat, 24 Aug 2002 09:45:48 -0700 Subject: New Freeware Download - Jammed: eric_koester@ccmail.mckee.com To: <trollbox@dustpuppy.mckee.com> From: "Diskeeper Product Manager, Executive Software" <executive@executive.com> List-Unsubscribe: <mailto:leave-html-sales1-21787251A@lyris.execsoft.com> Reply-To: executive@executive.com Message-Id: <LYRIS-21787251-20123-2002.08.24-09.47.15--eric_koester#ccmail.mckee.com@lyr is.execsoft.com> MIME-Version: 1.0 Content-Type: text/html; charset=us-ascii Spam-File: Envelope-Recipient: eric_koester@ccmail.mckee.com <!------------------------------------------------------------ Is Maximum System Performance and Reliablilty Important to you? Find out what you are missing! New Diskeeper Lite for Windows. IT'S FREE! * Includes the same advanced defragmentation technology used in Diskeeper 7.0. * Is much faster than the previous Diskeeper Lite and all built-in defragmenters. * Now runs on Windows NT®/98/2000/XP. Millions of downloads attest to the popularity of Diskeeper Lite, but it only ran on Windows NT 4.0. Now it's been updated for all Windows operating systems from Windows 98 onward.
A6: EMAIL_0005 | B6: isiNdebele | C6: Translation | D6: 0 | E6: legitimate | F6: SpamAssassin | G6: Fox <lds0062@cdc.net> | H6: razor-users@example.sourceforge.net | I6: Mon, 26 Aug 2002 16:14:04 -0400 | J6: [Razor-users] Preproc erasing message | K6: Ukulandelana kokulungisa amaphutha okulandelako kutjengisa imeyili yami ukusuka kuma-9295 wamabhayithi ukuya ku- 0 amabhayithi ngemva kokuthi i-preproc isebenze, okunginikela ikhodi yokuphuma engekho 0. Ngifake umlayezo ongezansi. Udahla I-Razor-Log: Akukho /etc/razor/razor-agent.conf etholakalako, yeqa. I-Razor-Log: Akukho razor-agent.conf etholakeleko, kusetjenziswa okujayelekileko. Aug 26 10:28:09.225237 check[3469]: [ 1] [bootup] Ukuloga kuthomile LogDebugLevel=9 ukuya ku-stdout Aug 26 10:28:09.225890 check[3469]: [ 5] computed razorhome=/etc/razor, conf=, ident=/etc/razor/identity Aug 26 10:28:09.226006 check[3469]: [ 2] Razor-Agents v2.14 ethoma razor-check -d -home=/etc/razor Aug 26 10:28:09.229704 check[3469]: [ 9] uname -a: Linux qmail.mckee.com 2.4.8-34.1mdk #1 Mon Nov 19 12:40:39 MST 2001 i686 akaziwa Aug 26 10:28:09.230155 hlola[3469]: [8] ukufunda i-RFC822 imeyili evela Aug 26 10:28:09.231524 hlola[3469]: [ 6] funda imeyili eyodwa Aug 26 10:28:09.231923 hlola[3469]: [8] Iinjini ezisekelwe_iklayenti: 1 2 3 4 Aug 26 10:28:09.233017 check[3469]: [ 8] prep_mail done: mail 1 headers=631, mime0=9295 Aug 26 10:28:09.233434 hlola[3469]: [6] ukweqa ifayela elimhlophe (elingenalutho?): /etc/razor/razor-whitelist Aug 26 10:28:09.233995 check[3469]: [ 5] read_file: 1 into efundwa ukusuka /etc/razor/servers.discovery.lst Aug 26 10:28:09.234369 check[3469]: [ 5] read_file: 1 into efundwa ukusuka /etc/razor/servers.nomination.lst Aug 26 10:28:09.234697 check[3469]: [ 5] read_file: 3 izinto ezifundwa ukusuka /etc/razor/servers.catalogue.lst Aug 26 10:28:09.235184 check[3469]: [ 9] Ukwabela ama-default ku honor.cloudmark.com Aug 26 10:28:09.235415 check[3469]: [ 9] Ukwabela ama-default ku truth.cloudmark.com Aug 26 10:28:09.235624 check[3469]: [ 9] Ukwabela ama-default ku fire.cloudmark.com Aug 26 10:28:09.235830 check[3469]: [ 9] Ukwabela ama-default ku apt.cloudmark.com Aug 26 10:28:09.236715 check[3469]: [ 5] read_file: 11 izinto ezifundwa ukusuka /etc/razor/server.truth.cloudmark.com.conf Aug 26 10:28:09.237368 check[3469]: [ 5] read_file: 11 izinto ezifundwa ukusuka /etc/razor/server.fire.cloudmark.com.conf Aug 26 10:28:09.237825 hlola[3469]: [5] 149643 imizuzwana ngaphambi kokutjhidela ukutholwa kweseva Aug 26 10:28:09.238135 check[3469]: [ 6] truth.cloudmark.com yikhathalogu Iseva srl ​​51; kubalwa i-min_cf=1, Iseva se: 0B Aug 26 10:28:09.238414 check[3469]: [ 8] Computed supported_engines: 1 2 4 Aug 26 10:28:09.238656 check[3469]: [ 8] Ukusebenzisa iseva eseduze truth.cloudmark.com:2703, cached info srl 51 Aug 26 10:28:09.238871 check[3469]: [ 8] imeyili 1 Isihloko: Ihlelo elitjha lamahhala Dawunlowuda Aug 26 10:28:09.290618 check[3469]: [ 6] preproc: iposi 1.0 yasuka ku-9295 amabhayithi ukuya ku-0, ukusula Aug 26 10:28:09.291100 check[3469]: [ 5] Ukuxhuma ku-truth.cloudmark.com ... Aug 26 10:28:09.505431 check[3469]: [ 8] Ukuxhumana kusungulwe Aug 26 10:28:09.505662 check[3469]: [ 4] truth.cloudmark.com >> 29 iseva ukubingelela: sn=C&srl=51&ep4=7542-10&a=l Aug 26 10:28:09.506086 check[3469]: [ 6] truth.cloudmark.com yikhathalogu Iseva srl ​​51; kubalwa i-min_cf=1, Iseva se: 0B Aug 26 10:28:09.506342 check[3469]: [ 8] Computed supported_engines: 1 2 4 Aug 26 10:28:09.506604 check[3469]: [ 8] imeyili 1.0 yeqiwe Aug 26 10:28:09.506686 check[3469]: [ 5] Akukho mibuzo, akukho spam Aug 26 10:28:09.506787 hlola[3469]: [5] ukuvala iseva truth.cloudmark.com Aug 26 10:28:09.507071 check[3469]: [ 4] truth.cloudmark.com << 5 Aug 26 10:28:09.507155 hlola[3469]: [ 6] a=q Aug 26 10:28:09.507959 hlola[3469]: [ 8] ukuhlola ngensingo kuqediwe ngempumelelo. >>Kusuka ku-bounce-html-sales1-21787251@lyris.execsoft.com ngoMvulo Aug 26 14:28:10 2002 Indlela yokubuya: <bounce-html-sales1-21787251@lyris.execsoft.com> Ithunyelwe-Ku: log@qmail.mckee.com Kwamukelwe: (i-qmail 3472 ebizwe kunethiwekhi); 26 Aug 2002 14:28:10 -0000 Yamukelwe: evela kongaziwako (HELO port-216-3073879-ds200.devices.datareturn.net) (216.46.231.87) ngo-10.97.5.1 nge-SMTP; 26 Aug 2002 14:28:05 -0000 I-X-Mailer: I-Lyris Web Interface Ilanga: uMgqibelo, mhlana ama-24 kuRhoboyi wee-2002 09:45:48 -0700 Isihloko: Ukudawuniloda kwe-Freeware etja - Jammed: eric_koester@ccmail.mckee.com Ku: <trollbox@dustpuppy.mckee.com> Ukusuka ku: "Umphathi womkhiqizo we-Diskeeper, i-Executive Software" <executive@executive.com> List-Unsubscribe: <mailto:leave-html-sales1-21787251A@lyris.execsoft.com> Phendula-ku: executive@executive.com Umlayezo-Id: <LYRIS-21787251-20123-2002.08.24-09.47.15--eric_koester#ccmail.mckee.com@lyr is.execsoft.com> I-MIME-Version: 1.0 Umhlobo wokuqukethwe: umtlolo/html; charset=us-ascii Ifayela le-Spam: Umamukeli wemvilophu: eric_koester@ccmail.mckee.com <!---------------------------------------------------------- Ingabe ukusebenza okuphezulu kwesistimu nokuthembeka kuqakathekile kuwe? Thola bona yini oyitlhogako! I-Diskieper etja ye-Windows. KUMAHHALA! * Ifaka hlangana ithekhnoloji efanako yokuhlukanisa ingcenye esetjenziswe ku- Isivikeli 7.0. * Ikhawuleza khulu kune-Diskeeper Lite yangaphambilini nayo yoke ama-defragmenters akhiwe ngaphakathi. * Nje isebenza ku-Windows NT®/98/2000/XP. Iingidigidi zokulandwa zifakazela ukuthandwa kwe-Diskeeper Lite, kodwana beyisebenza ku-Windows NT 4.0 kwaphela. Nje sele ivuselelwe kibo boke Iinhlelo zokusebenza ze-Windows ukusuka ku-Windows 98 ukuya phambili.
A7: EMAIL_0006 | B7: English | C7: Original | D7: 0 | E7: legitimate | F7: SpamAssassin | G7: "Joseph S. Barrera III" <joe@barrera.org> | H7: Eugen Leitl <eugen@leitl.org> | I7: Tue, 23 Jul 2002 14:46:04 -0700 | J7: Re: spam maps | K7: Eugen Leitl wrote: > P.S. We hate you, too. "Fuck you, sir," came the familiar tired chorus. "Louder!" "FUCK YOU, SIR!" Damn, I love that book (_Forever War_). - Joe http://xent.com/mailman/listinfo/fork | L7: http://xent.com/mailman/listinfo/fork
A8: EMAIL_0006 | B8: isiZulu | C8: Translation | D8: 0 | E8: legitimate | F8: SpamAssassin | G8: "Joseph S. Barrera III" <joe@barrera.org> | H8: Eugen Leitl <eugen@leitl.org> | I8: Tue, 23 Jul 2002 14:46:04 -0700 | J8: Mayelana: namamephu e-spam | K8: U-Eugen Leitl wabhala: > P.S. Nathi siyakuzonda. "Fuck you, sir," kwaphendula izwi elilodwa elijwayelekile nelikhathele. "Ngokuzwakalayo!" "FUCK YOU, SIR!" Hawu, ngiyayithanda leyo ncwadi (_Forever War_). - Joe http://xent.com/mailman/listinfo/fork | L8: http://xent.com/mailman/listinfo/fork
A9: EMAIL_0007 | B9: English | C9: Original | D9: 0 | E9: legitimate | F9: SpamAssassin | G9: Matthias Saou <matthias@rpmforge.net> | H9: rpm-zzzlist@freshrpms.net | I9: Mon, 07 Oct 2002 18:54:30 +0200 | J9: Re: transcode build problem (was: RH 8 no DMA for DVD drive) | K9: Once upon a time, Alvie wrote : > This is only the last part of it.I used 'rpmbuild --rebuild --without > avifile transcode.0.6.1-fr2.src.rpm'. > af6_decore.cpp:305: 'WAVEFORMATEX' > is used as a type, but is not defined as a > type. > af6_decore.cpp:306: parse error before `if' [...] All of these "af6" are related to avifile6 support :-/ Normally, my 0.6.1-fr2 build of transcode defaults to *not* use avifile, but you can use "--with avifile6" to force recompiling against it. Do you have an old avifile installed maybe? Can you check the "./configure ..." line run at the beginning of the rebuild process to see if it does include the "--without-avifile6" option? Matthias -- Clean custom Red Hat Linux rpm packages : http://freshrpms.net/ Red Hat Linux release 7.3 (Valhalla) running Linux kernel 2.4.18-10acpi Load : 0.23 0.14 0.14 _______________________________________________ RPM-List mailing list <RPM-List@freshrpms.net> http://lists.freshrpms.net/mailman/listinfo/rpm-list | L9: http://freshrpms.net/, http://lists.freshrpms.net/mailman/listinfo/rpm-list
A10: EMAIL_0007 | B10: isiZulu | C10: Translation | D10: 0 | E10: legitimate | F10: SpamAssassin | G10: Matthias Saou <matthias@rpmforge.net> | H10: rpm-zzzlist@freshrpms.net | I10: Mon, 07 Oct 2002 18:54:30 +0200 | J10: Mayelana: Inkinga yokwakha i-transcode (okwakuyi: i-RH 8 ayinayo i-DMA yedrayivu ye-DVD) | K10: Ngelinye ilanga, u-Alvie wabhala : > Le yingxenye yokugcina kuphela. Ngisebenzise 'rpmbuild --rebuild --without > avifile transcode.0.6.1-fr2.src.rpm'. > af6_decore.cpp:305: 'WAVEFORMATEX' > isetshenziswa njengohlobo (type), kodwa ayichazwanga njengo- > hlobo. > af6_decore.cpp:306: iphutha lokufunda ikhodi (parse error) ngaphambi kuka-`if' [...] Konke lokhu okungu-"af6" kuhlobene nokusekelwa kwe-avifile6 :-/ Ngokujwayelekile, uhlobo lwami lwe-transcode olungu-0.6.1-fr2 aluyisebenzisi i-avifile ngokuzenzakalelayo, kodwa ungasebenzisa u-"--with avifile6" ukuze uphoqelele ukuthi iphinde yakhiwe (recompile) isebenzisa yona. Ingabe kungenzeka ukuthi une-avifile endala efakiwe? Ungakwazi yini ukuhlola umugqa othi "./configure ..." osebenze ekuqaleni kwenqubo yokwakha kabusha ukuze ubone ukuthi uqukethe yini inketho ethi "--without-avifile6"? Matthias -- Amaphakethe e-rpm e-Red Hat Linux enziwe ngokwezifiso futhi ahlanzekile : http://freshrpms.net/ I-Red Hat Linux release 7.3 (Valhalla) esebenzisa i-Linux kernel 2.4.18-10acpi Umthwalo (Load) : 0.23 0.14 0.14 _______________________________________________ RPM-List mailing list <RPM-List@freshrpms.net> http://lists.freshrpms.net/mailman/listinfo/rpm-list | L10: http://freshrpms.net/, http://lists.freshrpms.net/mailman/listinfo/rpm-list
A11: EMAIL_0008 | B11: English | C11: Original | D11: 0 | E11: legitimate | F11: SpamAssassin | G11: David Wheeler <dwheeler@ida.org> | H11: Giorgio Zoppi <deneb@penguin.it>, secprog@securityfocus.com | I11: Fri, 30 Aug 2002 10:29:13 -0400 | J11: Re: Storing passwords | K11: If you need to store a database password, then clearly the first step is to store the text outside the web tree. You can encrypt it and store the encryption key elsewhere, so that at least an attacker has to get two different things. Also, don't get full privileges - create a user account that is GRANTed very limited access. However, you can often do better than this if security is critical. Create a separate program which has these database keys (as noted above), and make the web program contact IT. Create a very limited protocol that ONLY lets you do the operations you need (you can add specific operations later). There's a performance hit, which you're trading for improved data isolation. Giorgio Zoppi wrote: > On Fri, Aug 23, 2002, David Wheeler wrote: > > >>The standard way to store passwords is... not to >>store passwords. Instead, store a salted hash of >>the password in a database. When you get a purported >>password, you re-salt it, compute the hash, and >>determine if they are the same. This is how >>Unix has done it for years. You want bigger hashes >>and salts than the old Unix systems, and you still want >>to prevent reading from those files (to foil password crackers). >>More info is in my book at: >> http://www.dwheeler.com/secure-programs >> > > Well...but this cannot be applied to database password, which most > web apps use. The only solution I figure is store in clear outside web > tree, any other ideas feasible? > > Ciao, > Giorgio. > > -- > Never is Forever - deneb@penguin.it > Homepage: http://www.cli.di.unipi.it/~zoppi/index.html > -- > > > -- --- David A. Wheeler dwheeler@ida.org | L11: http://www.cli.di.unipi.it/~zoppi/index.html, http://www.dwheeler.com/secure-programs
A12: EMAIL_0008 | B12: isiNdebele | C12: Translation | D12: 0 | E12: legitimate | F12: SpamAssassin | G12: David Wheeler <dwheeler@ida.org> | H12: Giorgio Zoppi <deneb@penguin.it>, secprog@securityfocus.com | I12: Fri, 30 Aug 2002 10:29:13 -0400 | J12: Re: Storing passwords | K12: Nawufuna ukugcina iphasiwedi yedathabeyisi, khona-ke ngokusobala igadango lokuthoma kukugcina umtlolo ngaphandle umuthi wewebhu. Ungayibethela bese ubeka ikhiye yokubethela kwenye indawo, ukwenzela bona okungenani umhlaseli kufuze athole izinto ezimbili ezihlukileko. Godu, ungatholi amalungelo apheleleko - yenza i-akhawundi yomsebenzisi INIKEZWE ukufinyelela okulinganiselwe khulu. Kodwana, kanengi ungenza ngcono kunalokhu nangabe ukuphepha kuqakathekile. Yenza ihlelo elihlukileko elinalokhu iinkinobho zedathabeyisi (njengombana kutjhiwo ngehla), bese wenza ihlelo lewebhu thintana ne-IT. Yenza iphrothokholi elinganiselwe khulu ethi KUPHELA ikuvumela bona wenze imisebenzi oyitlhogako (ungangeza okuthileko imisebenzi ngemva kwesikhathi). Kunokudlala okukhulu, okwenza ukurhweba ukuthuthukisa ukuhlukaniswa kwedatha. U-Giorgio Zoppi watlola: > NgeLesihlanu, mhlazi-23 kuRhoboyi wee-2002, u-David Wheeler watlola: > > >>Indlela ejayelekileko yokugcina amaphasiwedi... ingasi >>gcina amaphasiwedi. Esikhundleni salokho, gcina i-hash enetswayi ye- >>iphasiwedi kudathabeyisi. Nawufumana >>iphasiwedi, uyifaka isawudo godu, ubale i-hash, bese >>hlola bona ziyafana na. Le yindlela >>I-Unix sele ikwenzile iminyaka eminengi. Ufuna ama-hash amakhulu >>namatswayi ukudlula amasistimu we-Unix amadala, begodu usafuna >>ukukhandela ukufundwa kilawo mafayela (ukukhandela ukuqeda iphasiwedi). >>Ilwazi elinabileko lisencwadini yami ku: >> http://www.dwheeler.com/secure-programs >> > > Kulungile...kodwana lokhu angeze kwasetjenziswa kuphasiwedi yedathabheyisi, okuyinto enengi > ukusetjenziswa kwama-app wewebhu. Isisombululo sodwa engicabangako sigcina ngaphandle kwewebhu ecacileko > umuthi, ikhona eminye imibono engenzekako? > > Ciao, > Giorgio. > > -- > Never is Forever - deneb@penguin.it > Ikhasi lokuthoma: http://www.cli.di.unipi.it/~zoppi/index.html > -- > > > -- --- U-David A. Wheeler dwheeler@ida.org | L12: http://www.cli.di.unipi.it/~zoppi/index.html, http://www.dwheeler.com/secure-programs
A13: EMAIL_0011 | B13: English | C13: Original | D13: 0 | E13: legitimate | F13: SpamAssassin | G13: scripting <rssfeeds@example.com> | H13: yyyy@example.com | I13: Thu, 26 Sep 2002 08:01:30 -0000 | J13: Jeremy Bowers: "None of the trackback mechanisms has reached the critical m | K13: URL: http://scriptingnews.userland.com/backissues/2002/09/25#When:5:12:19AM Date: Wed, 25 Sep 2002 12:12:19 GMT Jeremy Bowers[1]: "None of the trackback mechanisms has reached the critical mass necessary to see the negative effects experienced in all other community models." [1] http://www.jerf.org/irights/2002/09/25.html#a2231 | L13: http://scriptingnews.userland.com/backissues/2002/09/25#When:5:12:19AM, http://www.jerf.org/irights/2002/09/25.html#a2231
A14: EMAIL_0011 | B14: isiZulu | C14: Translation | D14: 0 | E14: legitimate | F14: SpamAssassin | G14: scripting <rssfeeds@example.com> | H14: yyyy@example.com | I14: Thu, 26 Sep 2002 08:01:30 -0000 | J14: UJeremy Bowers: "Azikho izindlela zokulandela umkhondo ezifinyelele ku-m | K14: URL: http://scriptingnews.userland.com/backissues/2002/09/25#When:5:12:19AM Usuku: NgoLwesithathu, 25 Septhemba 2002 12:12:19 GMT Jeremy Bowers[1]: "Ayikho neyodwa yezindlela ze-'trackback' esifinyelele ezingeni elibalulekile elidingekayo ukuze kubonakale imiphumela emibi ebonakala kuzo zonke ezinye izinhlobo zemiphakathi." [1] http://www.jerf.org/irights/2002/09/25.html#a2231 | L14: http://scriptingnews.userland.com/backissues/2002/09/25#When:5:12:19AM, http://www.jerf.org/irights/2002/09/25.html#a2231
A15: EMAIL_0013 | B15: English | C15: Original | D15: 0 | E15: legitimate | F15: SpamAssassin | G15: mb/vipul@dcs.qmul.ac.uk | H15: Joe Berry <joe@topshot.com> | I15: Mon, 26 Aug 2002 21:04:35 +0100 | J15: Re[2]: [Razor-users] Reducing impact from tons of email | K15: On Aug 25 Joe Berry wrote: >Very good advice given above. Yes :) >One more problem solved. No. One more problem in some software worked around by using tricks in another piece of software. The solution is the aggregator. ------------------------------------------------------- This sf.net email is sponsored by: OSDN - Tired of that same old cell phone? Get a new here for FREE! https://www.inphonic.com/r.asp?r=sourceforge1&refcode1=vs3390 _______________________________________________ Razor-users mailing list Razor-users@lists.sourceforge.net https://lists.sourceforge.net/lists/listinfo/razor-users | L15: https://lists.sourceforge.net/lists/listinfo/razor-users, https://www.inphonic.com/r.asp?r=sourceforge1&refcode1=vs3390
A16: EMAIL_0013 | B16: isiZulu | C16: Translation | D16: 0 | E16: legitimate | F16: SpamAssassin | G16: mb/vipul@dcs.qmul.ac.uk | H16: Joe Berry <joe@topshot.com> | I16: Mon, 26 Aug 2002 21:04:35 +0100 | J16: Re[2]: [Razor-users] Ukunciphisa umthelela wenqwaba yama-imeyili | K16: Ngo-Agasti 25 uJoe Berry wabhala: >Iseluleko esihle kakhulu esinikezwe ngenhla. Yebo :) >Enye inkinga ixazululiwe. Cha. Enye inkinga kuhlelo oluthile lwekhompyutha ixazululwe ngokusebenzisa amaqhinga kolunye uhlelo. Isixazululo siwuhlelo oluhlanganisayo (aggregator). ------------------------------------------------------- Le-imeyili ye-sf.net ixhaswe yi: OSDN - Ukhathele yilelo foni yakudala? Thola entsha lapha mahhala! https://www.inphonic.com/r.asp?r=sourceforge1&refcode1=vs3390 _______________________________________________ Uhlu lwama-imeyili lwabasebenzisi be-Razor Razor-users@lists.sourceforge.net https://lists.sourceforge.net/lists/listinfo/razor-users | L16: https://lists.sourceforge.net/lists/listinfo/razor-users, https://www.inphonic.com/r.asp?r=sourceforge1&refcode1=vs3390
A17: EMAIL_0014 | B17: English | C17: Original | D17: 0 | E17: legitimate | F17: SpamAssassin | G17: bugzilla-daemon@hughes-family.org | H17: spamassassin-devel@example.sourceforge.net | I17: Sat, 21 Sep 2002 16:37:55 -0700 | J17: [SAdev] [Bug 886] Add a rule to detect Content-type message/partial | K17: http://www.hughes-family.org/bugzilla/show_bug.cgi?id=886 ------- Additional Comments From jm@jmason.org 2002-09-21 16:37 ------- I'd prefer to wait and see if spammers do anything about it. my guess is they will not, as it'd mean modifying their spamware to send >1 msg per recipient. I vote WONTFIX as a result ;) ------- You are receiving this mail because: ------- You are the assignee for the bug, or are watching the assignee. ------------------------------------------------------- This sf.net email is sponsored by:ThinkGeek Welcome to geek heaven. http://thinkgeek.com/sf _______________________________________________ Spamassassin-devel mailing list Spamassassin-devel@lists.sourceforge.net https://lists.sourceforge.net/lists/listinfo/spamassassin-devel | L17: http://thinkgeek.com/sf, http://www.hughes-family.org/bugzilla/show_bug.cgi?id=886, https://lists.sourceforge.net/lists/listinfo/spamassassin-devel
A18: EMAIL_0014 | B18: isiZulu | C18: Translation | D18: 0 | E18: legitimate | F18: SpamAssassin | G18: bugzilla-daemon@hughes-family.org | H18: spamassassin-devel@example.sourceforge.net | I18: Sat, 21 Sep 2002 16:37:55 -0700 | J18: [SAdev] [Iphutha 886] Faka umthetho wokuthola i-Content-type ethi umyalezo/okuyingxenye | K18: http://www.hughes-family.org/bugzilla/show_bug.cgi?id=886 ------- Amazwana engeziwe avela ku-jm@jmason.org 2002-09-21 16:37 ------- Ngingakhetha ukulinda ngibone ukuthi abathumela imiyalezo engafuneki (spammers) benza okuthile ngakho yini. Ngicabanga ukuthi ngeke bakwenze lokho, ngoba kungasho ukushintsha isofthiwe yabo ukuze bathumele imiyalezo engaphezu koyedwa kumamukeli ngamunye. Ngakho-ke ngivotela inketho ethi WONTFIX ;) ------- Uthola le-imeyili ngoba: ------- Ungumuntu owabelwe ukulungisa le nkinga (bug), noma uqaphe lowo oyabelwe yona. ------------------------------------------------------- Le-imeyili ye-sf.net ixhaswe yi-ThinkGeek Siyakwamukela ezweni lamaphupho labathandi bobuchwepheshe (geek heaven). http://thinkgeek.com/sf _______________________________________________ Uhlu lwe-imeyili lwe-Spamassassin-devel Spamassassin-devel@lists.sourceforge.net https://lists.sourceforge.net/lists/listinfo/spamassassin-devel | L18: http://thinkgeek.com/sf, http://www.hughes-family.org/bugzilla/show_bug.cgi?id=886, https://lists.sourceforge.net/lists/listinfo/spamassassin-devel
... A22: EMAIL_0016 | B22: isiNdebele | C22: Translation | D22: 0 | E22: legitimate | F22: SpamAssassin | G22: Kenn Humborg <kenn@linux.ie> | H22: John Gay <johngay@eircom.net> | I22: Sun, 21 Jul 2002 19:16:30 +0100 | J22: Re: [ILUG] Optimising for PentiumMMX? | K22: NgeSonto, mhlazi-21 kuNtaka 2002 nge-07:06:06PM +0100, u-John Gay watlola: > Ngiyazibuza bona i-C, namanye amalayibhrari kufanele akhiwe kabutjha? Bangakghona na > sebenzisa ithuba lemiyalo ye-Pentium ne-MMX malungana nokusebenza kwesistimu? > Begodu ingabe lokhu kutlhoga ukwakhiwa kabutjha kwe-gcc nayo? i-glibc ngumuntu ongakhethwa. > Ngenothi ehlobene, ngiyazi bona ngike ngakhuluma lapha ngaphambilini, kodwana ngisafuna > ye-Slot 1 550Mhz PIII. Irherho lami elijayelekileko yi-Dual PII350 kanye ne-440BX > M/B angathatha ama-PIII. Ngikghone ukuthola izandla zami kwenye. Ukube bengingathola enye > Ngingafaka ama-PIII amabili ebhokisini bese ngihlanganisa i-X ukusebenzisa i- > Imilayo ye-SSE/Katmai ku-PIII. Angicabangi bona kufanele ukubuyiselwa esikhundleni > ama-PII amabili nge-PIII eyodwa. Ngiyazi bona azisekho esitokisini, begodu ngiyazibukela > i-Buy-N-Sell qobe, kodwana ngaphandle kokuthenga ihlelo elizeleko le-PIII, angikaze > waba netjhudu elikhulu. Hlala uqale i-eBay. Okunye okucasulako nge-eBay kukuthi abathengisi abanengi bathi "bazo ukuthunyelwa e-US kwaphela". Kodwana, ngifumene bona nangabe ubuza kuhle, bazo kuvamise ukuthunyelwa lapha. Ukubhadela, yenza i-akhawunti ye-paypal nofana thumela umthengisi idrafti yebhanka yedola le-US. Nginezinto ezinengi ezincani begodu iingcenye ngaleyo ndlela (ngokwesibonelo, ekugcineni ngathola ikhithi yokubeka i-rackmount ye- iseva yami yetheminali ye-DECserver 700 ebengisolo ngiyifuna iminyaka eminengi, isamba se-US$15). Lokha, Kenn -- Isiqhema sabasebenzisi be-Irish Linux: ilug@linux.ie http://www.linux.ie/mailman/listinfo/ilug ukuthola ilwazi lokubhalisa. Umgcini woluhlu: listmaster@linux.ie | L22: http://www.linux.ie/mailman/listinfo/ilug
A23: EMAIL_0017 | B23: English | C23: Original | D23: 0 | E23: legitimate | F23: SpamAssassin | G23: yyyy@example.com | H23: Gary Lawrence Murphy <garym@canada.com> | I23: Tue, 17 Sep 2002 17:50:23 +0100 | J23: Re: Slaughter in the Name of God | K23: Gary Lawrence Murphy said: > >>>>> "S" == Stephen D Williams <sdw@lig.net> writes: > S> A) Which religion is it that can claim no foul actions in its > S> past? Certainly not Christianity, Islam, etc. > Rastafari. > That is, if you concede that of the two founding branches, only the > one founded by the Nyabingi were legit and the others were > thinly-veneered anti-colonial hooligans. > There is also Vietnamese Buddhism, unless you count setting fire to > oneself as a "foul action". What about Tibetan Buddhism BTW? They seem like an awfully nice bunch of chaps (and chapesses). > When we launched the Native Net in 1989, one of the first things we > noticed on networking aboriginal groups around the world is that the > British Army, with the US Army as a proxy by extension, were the > common thread. Where neither was present (physically or through > influence) there /tended/ to be less violence. > > The issue in Ireland is complex, but rest assured that religious > aspects are only a co-incidence of the invader/colonials being > predominantly members of the Royal-headed Anglicans and the aboriginal > population being predominantly members of the Pope-headed Catholics. > The conflict itself has nothing to do with ideology or practice, since > the Anglican Church is a near-identical clone of Catholicism. > > (now I bet that's going to attract some healthy debate ;) Man, I'm not going *there* again ;) I'll agree, though, that the ideology or practices of the religions have very little to do with the conflict. > The same is true of street-gangs: When people are disenfranchised, > it's easier to offer them the Triad as a new family. You get > cellphones, cars, a dry place to live. Triad, biker gangs, mafia, the > IRA, Al Queda ... we've been fighting the War on Terrorism for as long > as there's been commerce, so you'd think we'd /realize/ that > escalation of violence is not a solution. Well said! --j.
A24: EMAIL_0017 | B24: Afrikaans | C24: Translation | D24: 0 | E24: legitimate | F24: SpamAssassin | G24: yyyy@example.com | H24: Gary Lawrence Murphy <garym@canada.com> | I24: Tue, 17 Sep 2002 17:50:23 +0100 | J24: Re: Slagting in die Naam van God | K24: Gary Lawrence Murphy het gesê: > >>>>> "S" == Stephen D Williams <sdw@lig.net> skryf: > S> A) Watter godsdiens kan beweer dat dit geen gemene dade in sy > S> verlede het nie? Beslis nie die Christendom, Islam, ens. nie. > Rastafari. > Dit is, as jy toegee dat van die twee stigtingstakke net die > een wat deur die Nyabingi gestig is, eg was en die ander > antikoloniale boewe met 'n dun lagie vernis was. > Daar is ook Viëtnamese Boeddhisme, tensy jy om jouself aan die brand te steek > as 'n "gemene daad" tel. Wat van Tibettaanse Boeddhisme terloops? Hulle lyk na 'n verskriklik gawe klomp ouens (en meisies). > Toe ons die Native Net in 1989 bekendgestel het, was een van die eerste dinge wat ons > opgemerk het toe ons inheemse groepe regoor die wêreld in 'n netwerk verbind het, dat die > Britse Weermag, met die Amerikaanse Weermag by uitbreiding as plaasvervanger, die > gemeenskaplike draad was. Waar nie een van die twee teenwoordig was nie (fisies of deur > invloed) was daar /gewoonlik/ minder geweld. > > Die kwessie in Ierland is kompleks, maar wees verseker dat godsdienstige > aspekte slegs 'n toeval is van die feit dat die indringers/koloniste > hoofsaaklik lede was van die Anglikane met die koning aan die hoof, en die inheemse > bevolking hoofsaaklik lede van die Katolieke met die Pous aan die hoof. > Die konflik self het niks met ideologie of praktyk te doen nie, aangesien > die Anglikaanse Kerk 'n byna identiese kloon van Katolisisme is. > > (nou wed ek dit gaan 'n gesonde debat uitlok ;) Man, ek gaan nie weer *daarheen* nie ;) Ek sal egter saamstem dat die ideologie of praktyke van die godsdienste baie min met die konflik te doen het. > Dieselfde geld vir straatbendes: wanneer mense ontmagtig is, > is dit makliker om hulle die Triade as 'n nuwe familie aan te bied. Jy kry > selfone, motors, 'n droë plek om te woon. Triades, motorfietsbendes, die mafia, die > IRA, Al Qaeda ... ons veg die Oorlog teen Terreur al so lank > as wat daar handel is, so 'n mens sou dink ons sou /besef/ dat > die eskalasie van geweld nie 'n oplossing is nie. Goed gesê! --j. | M24: 2 | N24: 2
A25: EMAIL_0017 | B25: isiXhosa | C25: Translation | D25: 0 | E25: legitimate | F25: SpamAssassin | G25: yyyy@example.com | H25: Gary Lawrence Murphy <garym@canada.com> | I25: Tue, 17 Sep 2002 17:50:23 +0100 | J25: Re: Ukubulawa eGameni likaThixo | K25: UGary Lawrence Murphy wathi: > >>>>> "S" == Stephen D Williams <sdw@lig.net> ubhala wathi: > S> A) Yiyiphi inkolo enokubanga ukuba ayinazenzo zimbi kwixesha layo > S> elidlulileyo? Ngokuqinisekileyo asiloKrestu, ubuSilamsi, njl. > Rastafari. > Oko kukuthi, ukuba uyavuma ukuba kumasebe amabini asungulayo, kuphela > lelo elasekwa yi-Nyabingi elaliyinyani kwaye amanye ayengamaphukuphuku > alwa nobukoloniyali anengubo ecekethekileyo. > Kukwakho nobuBhedha baseVietnam, ngaphandle kokuba uthatha ukuzitshisa > njenge-"senzo esibi". Kuthekani ngobuBhedha baseTibet ngokunjalo? Babonakala beliqela lamadoda (namabhinqa) anobubele kakhulu. > Xa sasungula i-Native Net ngo-1989, enye yezinto zokuqala esaziqaphelayo > xa sasidibanisa amaqela emveli kwihlabathi liphela yayikukuba > uMkhosi waseBritani, kunye noMkhosi wase-US njengommeli ngokwandiswa, yayingumsonto oqhelekileyo. Apho kungekho namnye kubo (ngokwenyama okanye > ngempembelelo) kwakukholisa ukubakho ubundlobongela obuncinci. > > Umba ose-Ireland unzima, kodwa qiniseka ukuba iinkalo zenkolo > ziziganeko nje zokuhambelana kwenyani yokuba abahlaseli/abakoloniyali > babengamalungu e-Anglikani ekhokelwa nguKumkani kwaye abemi bomthonyama > babengamalungu amaKatolika akhokelwa nguPopu. > Imbambano ngokwayo ayinanto yakwenza nengcamango okanye ukwenza, kuba > iCawa yase-Anglikani iphantse yafana nqo nobuKatolika. > > (ngoku ndiyabheja ukuba oku kuza kutsala ingxoxo-mpikiswano ephilileyo ;) Mfondini, andizukuya *apho* kwakhona ;) Nangona kunjalo ndiyavuma ukuba ingcamango okanye izenzo zeenkolo zinenxaxheba encinci kakhulu kule mbambano. > Kukwanjalo nakwimigulukudu yasezitalatweni: Xa abantu behluthiwe amalungelo, > kulula ukubanika i-Triad njengosapho olutsha. Ufumana > iiselfowuni, iimoto, indawo eyomileyo yokuhlala. I-Triad, imigulukudu yezithuthuthu, i-mafia, i-IRA, > i-Al Qaeda ... kudala silwa iMfazwe noBunqolobi ukusukela oko > kwabakho urhwebo, ngoko ungacinga ukuba siyakwazi ukubona ukuba > ukonyuka kobundlobongela asisosicazululo. Kuthethwe kakuhle! --j.
A26: EMAIL_0018 | B26: English | C26: Original | D26: 0 | E26: legitimate | F26: SpamAssassin | G26: Panu Matilainen <pmatilai@welho.com> | H26: rpm-zzzlist@freshrpms.net | I26: Tue, 08 Oct 2002 11:43:09 +0300 | J26: Re: a problem with apt-get | K26: On Mon, 7 Oct 2002, Thomas Vander Stichele wrote: > Hi, > > In my build scripts, I have problems with some of the kernel packages. > > For kernel-sources, I get : > > Package kernel-source is a virtual package provided by: > kernel-source#2.4.18-3 2.4.18-3 > kernel-source#2.4.18-3 2.4.18-3 > > on running apt-get install kernel-source > > Now, first of all, this doesn't really tell me what the two options are ;) > Second, is there some way I can tell apt-get to install either ? This is > done from automatic build scripts so I'd like it to proceed anyway. That's just apt's way of telling you the package is in "AllowDuplicated", meaning multiple versions of the package can be installed at the same time. Yes the output is a bit strange.. especially when there's only one version available. 'apt-get install kernel-source#2.4.18-3' will install it... -- - Panu - _______________________________________________ RPM-List mailing list <RPM-List@freshrpms.net> http://lists.freshrpms.net/mailman/listinfo/rpm-list | L26: http://lists.freshrpms.net/mailman/listinfo/rpm-list
A27: EMAIL_0018 | B27: Afrikaans | C27: Translation | D27: 0 | E27: legitimate | F27: SpamAssassin | G27: Panu Matilainen <pmatilai@welho.com> | H27: rpm-zzzlist@freshrpms.net | I27: Tue, 08 Oct 2002 11:43:09 +0300 | J27: Re: 'n probleem met apt-get | K27: Op Ma, 7 Okt 2002, het Thomas Vander Stichele geskryf: > Hallo, > > In my bouskripte het ek probleme met sommige van die kernpakkette. > > Vir kernel-sources kry ek: > > Package kernel-source is a virtual package provided by: > kernel-source#2.4.18-3 2.4.18-3 > kernel-source#2.4.18-3 2.4.18-3 > > wanneer ek apt-get install kernel-source laat loop > > Nou, eerstens sê dit nie regtig vir my wat die twee opsies is nie ;) > Tweedens, is daar 'n manier waarop ek apt-get kan sê om enigeen te installeer? Dit word > vanuit outomatiese bouskripte gedoen, so ek wil hê dit moet in elk geval voortgaan. Dit is net apt se manier om jou te sê dat die pakket in "AllowDuplicated" is, wat beteken dat veelvuldige weergawes van die pakket terselfdertyd geïnstalleer kan word. Ja, die uitvoer is 'n bietjie vreemd.. veral wanneer daar net een weergawe beskikbaar is. 'apt-get install kernel-source#2.4.18-3' sal dit installeer... -- - Panu - _______________________________________________ RPM-List-poslys <RPM-List@freshrpms.net> http://lists.freshrpms.net/mailman/listinfo/rpm-list | L27: http://lists.freshrpms.net/mailman/listinfo/rpm-list | M27: 2 | N27: 3
A28: EMAIL_0018 | B28: isiXhosa | C28: Translation | D28: 0 | E28: legitimate | F28: SpamAssassin | G28: Panu Matilainen <pmatilai@welho.com> | H28: rpm-zzzlist@freshrpms.net | I28: Tue, 08 Oct 2002 11:43:09 +0300 | J28: Re: ingxaki nge-apt-get | K28: NgoMvulo, 7 Okt 2002, uThomas Vander Stichele wabhala: > Molo, > > Kwizikripthi zam zokwakha, ndineengxaki ngezinye zeepakheji ze-kernel. > > Kwi-kernel-sources ndifumana: > > Package kernel-source is a virtual package provided by: > kernel-source#2.4.18-3 2.4.18-3 > kernel-source#2.4.18-3 2.4.18-3 > > xa ndiqhuba i-apt-get install kernel-source > > Ngoku, okokuqala oku akundixeleli ngokwenene ukuba zeziphi iinketho ezimbini ;) > Okwesibini, ingaba ikho indlela endifanele ndixelele ngayo i-apt-get ukuba ifakele nokuba yeyiphi na? Oku kwenziwa > kwizikripthi zokwakha ezizenzekelayo, ngoko ndingathanda ukuba iqhubeke nokuba kungenjani. Yindlela nje ye-apt yokukuxelela ukuba iphakheji ikwi-"AllowDuplicated", oku kuthetha ukuba iinguqulelo ezininzi zephakheji zinokufakelwa ngaxeshanye. Ewe, imveliso iyamangalisa kancinci.. ngakumbi xa kukho kuphela inguqulelo enye ekhoyo. 'apt-get install kernel-source#2.4.18-3' iya kuyifakela... -- - Panu - _______________________________________________ Uluhlu lwemeyile lwe-RPM-List <RPM-List@freshrpms.net> http://lists.freshrpms.net/mailman/listinfo/rpm-list | L28: http://lists.freshrpms.net/mailman/listinfo/rpm-list
A29: EMAIL_0019 | B29: English | C29: Original | D29: 0 | E29: legitimate | F29: SpamAssassin | G29: Chris Haun <chris@noskillz.com> | H29: Gregory Alan Bolcer <gbolcer@endeavors.com> | I29: Sat, 28 Sep 2002 12:21:17 -0400 | J29: Re: EBusiness Webforms: cluetrain has left the station | K29: I'll agree that webforms are a pain in the ass, however it would seem to me that the problem with passport is the same one you noted with the autoform function, providing more info than you want to. That and some entity would be holding the passport info, thus have all that data in the first place. Personally i'd never trust them not to at least use it internally to market to me, if not sell/rent out. Just think of the ability they'd have to build a profile for you since everything you went to was tracked to you. And thats just the marketing side of it. Chris On Sat, 28 Sep 2002, Gregory Alan Bolcer wrote: > What's wrong with doing business over the Web? Web forms. There's > promising replacements forms, but this is the current state of the > industry: > > o You find something that you want to fill out. It's a partnership form, > a signup for a Web seminar, a request for more information, anything. > o You start wasting time typing in all those stupid fields and spend > about 10 minutes going through all their stupid qualification hoops > just to get a small piece of information , whitepaper, or a callback > when halfway through, you start to wonder if it's really worth your > time to forever be stuck on their stupid prospect list. > o Pull down tags are never put in order of use instead of alphabetized. > I was on a site just now that had every single country in the world > listed; the selection of your country was absolutely critical for you > to hit submit, but due to the layout, the "more>" tag on the second > row was offscreen so it was impossible to select any country except > about two dozen third world countries. > o Even worse, ever time you hit submit, all forms based things complain > about using the universal country phone number format and will cause > you to re-enter dashes instead of dots. > o When you get something that's not entered right, you will go back and > enter it right, but then some other field or most likely pulldown will > automatically get reset to the default value so that you will have to > go back and resent that freaking thing too. Finally after all combinations > of all pulldowns, you may get a successful submit. > o You wait freaking forever just to get a confirmation. > o Sometimes, like today, you won't be able to ever submit anything due > to it being impossible to ever submit a valid set of information that > is internally non-conflicting according to whatever fhead wrote their > forms submission. > > What's wrong with this picture? The company is screwing you by wasting > your time enforcing their data collection standards on you. I'm sure there's > someone in that company that would be willing to accept "US", "U.S", "USA" > "United States", "U of A", "America", etc. and would know exactly which > freaking country the interested party was from instead of forcing them > to waste even more time playing Web form geography. > > I'm starting to see the light of Passport. You want more information? Hit > this passport button. Voila. IE6 and Netscape 6,7 have pre-forms sutff, > but I always turn it off because you never know when there's that one field > that you don't want to submit to the person you are submitting to that > automatically gets sent, i.e. the privacy stuff is well beyond the > average user who will get screwed on privacy stuff. > > So, if crappy forms-based submission is the state of practice for > business enablement on the Web, I can't see this whole data submission > and hurry up and wait for us to get back to you business process as > working all that well. > > > Greg >
A30: EMAIL_0019 | B30: isiZulu | C30: Translation | D30: 0 | E30: legitimate | F30: SpamAssassin | G30: Chris Haun <chris@noskillz.com> | H30: Gregory Alan Bolcer <gbolcer@endeavors.com> | I30: Sat, 28 Sep 2002 12:21:17 -0400 | J30: Mayelana nama-Webform e-EBusiness: isitimela sesihambile | K30: Ngiyavuma ukuthi amafomu aku-inthanethi ayacasula kakhulu, kodwa kimi kubonakala sengathi inkinga nge-Passport iyafana naleyo oyiphawule ngomsebenzi we-autoform, okungukuthi unikeza ulwazi olungaphezu kwalolo ofuna ukulunikeza. Ngaphezu kwalokho, kukhona inhlangano ezobe iphethe imininingwane ye-Passport, ngakho-ke izobe inayo yonke leyo mininingwane kwasekuqaleni. Ngokwami, ngeke ngibathembe ukuthi ngeke bayisebenzise okungenani ngaphakathi enhlanganweni yabo ukungikhangisela izinto, noma bayidayise noma bayiqashise kwabanye. Cabanga nje ngekhono abangaba nalo lokwakha iphrofayili yakho njengoba yonke into oyivakashelayo yayilandelelwa kuwe. Futhi lokho kunguhlangothi lokukhangisa kuphela lwale ndaba. Chris NgoMgqibelo, mhla zingama-28 kuMandulo (September) 2002, uGregory Alan Bolcer wabhala: Yini inkinga ngokwenza ibhizinisi nge-inthanethi? Amafomu aku-inthanethi. Kukhona izindlela ezintsha ezithembisayo zokuthatha indawo yawo, kodwa yilesi isimo samanje salomkhakha: o Uthola into ofuna ukuyigcwalisa. Kungaba ifomu lobambiswano, ukubhalisela isemina eku-inthanethi, isicelo solwazi olwengeziwe, noma yini. o Uqala ukuchitha isikhathi uthayipha yonke leyo migqa engenangqondo futhi uchitha cishe imizuzu eyi-10 udlula kuzo zonke izinqubo zabo eziyinkimbinkimbi nezingenangqondo ukuze nje uthole ulwazi oluncane, umbiko (whitepaper), noma ucingo olubuyayo, kanti phakathi nendawo, uqala ukuzibuza ukuthi ingabe kuyafanele yini ukuchitha isikhathi sakho ukuze uhlale unomphela ohlwini lwabo lwamakhasimende angaba khona. o Amamenyu okukhetha (pulldown menus) awahlelwa ngokwendlela asetshenziswa ngayo, kodwa ahlelwa ngokwe-alfabhethi. Bengisanda kuvakashela iwebhusayithi ebifaka amazwe wonke omhlaba; ukukhetha izwe lakho bekubaluleke kakhulu ukuze ukwazi ukucindezela inkinobho yokuthumela (submit), kodwa ngenxa yokwakheka kwekhasi, inketho ethi "more>" (okwengeziwe) emgqeni wesibili ibingabonakali esikrinini, ngakho bekungenakwenzeka ukukhetha noma yiliphi izwe ngaphandle kwamazwe ambalwa asathuthuka. o Okubi nakakhulu, njalo uma ucindezela inkinobho yokuthumela, uhlelo lukhononda ngendlela yokubhala inombolo yocingo (ifomethi yamazwe ngamazwe) futhi lukuphoqa ukuthi ufake imigqa emincane (dashes) esikhundleni samachashazi. o Uma kukhona okungafakwanga kahle, ubuyela emuva ukuyilungisa, kodwa bese omunye umugqa noma imenyu yokukhetha ibuyela esimweni sayo sokuqala ngokuzenzakalelayo, okukwenza uphinde ubuyele emuva ukuyilungisa nayo leyo nto ecasulayo. Ekugcineni, ngemva kokuzama zonke izinketho, mhlawumbe uyaphumelela ukuthumela ulwazi. o Ulinda isikhathi eside ngokwedlulele ukuze nje uthole isiqinisekiso. > o Kwesinye isikhathi, njenganamuhla, ngeke ukwazi ukuthumela lutho ngenxa > yokuthi akunakwenzeka ukuthumela imininingwane efanele engangqubuzani > ngaphakathi, kuye ngokuthi ubani lowo owenza uhlelo lokugcwalisa amafomu. > > Yini engalungile ngalokhu? Inkampani ikwenza ube nesikhathi esinzima ngokuchitha > isikhathi sakho ikuphoqa ukuthi ulandele izindinganiso zayo zokuqoqa imininingwane. > Ngiyaqiniseka ukuthi kukhona umuntu kuleyo nkampani ongavuma ukwamukela okuthi > "US", "U.S", "USA", "United States", "U of A", "America", njll., futhi ozoqonda > kahle ukuthi lelo qembu elithintekayo livela kuliphi izwe, kunokuba libaphoqe > ukuthi bachithe isikhathi esengeziwe bedlala umdlalo wokucabanga indawo > ukuze bagcwalise amafomu e-inthanethi. > > Sengiqala ukubona izinzuzo ze-Passport. Ufuna imininingwane eyengeziwe? > Cindezela le nkinobho ye-passport. Sekulungile. I-IE6 ne-Netscape 6, 7 zinazo > izici zokugcwalisa amafomu kusengaphambili, kodwa ngihlale ngizivala ngoba > awusoze wazi ukuthi ikhona yini leyo nkambu (field) ongayifuni ukuyithumela > kumuntu oyithumelela imininingwane kodwa ithunyelwa ngokuzenzakalelayo; > okusho ukuthi izindaba zobumfihlo ziyinkimbinkimbi kakhulu kumsebenzisi > ojwayelekile, okungenzeka ukuthi uzolahlekelwa yilungelo lakhe lobumfihlo. > > Ngakho-ke, uma ukuthumela imininingwane ngamafomu angenamsebenzi kuyindlela > ejwayelekile yokwenza ibhizinisi ku-inthanethi, angiboni sengathi le nqubo > yokuthumela imininingwane bese ulinda isikhathi eside ukuthi babuye kuwe > izosebenza kahle ngempela. > > > Greg >
A31: EMAIL_0020 | B31: English | C31: Original | D31: 0 | E31: legitimate | F31: SpamAssassin | G31: Mark Derricutt <mark@talios.com> | H31: freshrpms <rpm-zzzlist@freshrpms.net> | I31: Sun, 03 Feb 2002 10:19:27 +1300 | J31: creating rpms with subdirs (install command) | K31: Hi, I'm building an rpm for the resin webserver, and I basically want to install the entire tarball under a diretory, but, the tarball includes subdirectorys, in my spec i have: install -s -m 755 %{name}-%{version}.%{release}/* \ $RPM_BUILD_ROOT/usr/local/resin and I'm getting: install: `resin-2.0.5/bin' is a directory install: `resin-2.0.5/conf' is a directory Is there a proper/nice way I should handle this? -- \m/ -- "...if I seem super human I have been misunderstood." (c) Dream Theater mark@talios.com - ICQ: 1934853 JID: talios@myjabber.net _______________________________________________ RPM-List mailing list <RPM-List@freshrpms.net> http://lists.freshrpms.net/mailman/listinfo/rpm-list | L31: http://lists.freshrpms.net/mailman/listinfo/rpm-list
A32: EMAIL_0020 | B32: Afrikaans | C32: Translation | D32: 0 | E32: legitimate | F32: SpamAssassin | G32: Mark Derricutt <mark@talios.com> | H32: freshrpms <rpm-zzzlist@freshrpms.net> | I32: Sun, 03 Feb 2002 10:19:27 +1300 | J32: rpms met subgidse skep (install-opdrag) | K32: Hallo, ek bou 'n rpm vir die resin-webbediener, en ek wil basies die hele tarball onder 'n gids installeer, maar die tarball sluit subgidse in. In my spec het ek: install -s -m 755 %{name}-%{version}.%{release}/* \ $RPM_BUILD_ROOT/usr/local/resin en ek kry: install: `resin-2.0.5/bin' is a directory install: `resin-2.0.5/conf' is a directory Is daar 'n behoorlike/netjiese manier waarop ek dit moet hanteer? -- \m/ -- "...as ek bomenslik lyk, word ek verkeerd verstaan." (c) Dream Theater mark@talios.com - ICQ: 1934853 JID: talios@myjabber.net _______________________________________________ RPM-List-poslys <RPM-List@freshrpms.net> http://lists.freshrpms.net/mailman/listinfo/rpm-list | L32: http://lists.freshrpms.net/mailman/listinfo/rpm-list | M32: 2 | N32: 3
A33: EMAIL_0020 | B33: isiXhosa | C33: Translation | D33: 0 | E33: legitimate | F33: SpamAssassin | G33: Mark Derricutt <mark@talios.com> | H33: freshrpms <rpm-zzzlist@freshrpms.net> | I33: Sun, 03 Feb 2002 10:19:27 +1300 | J33: ukudala ii-rpm ezineenkovu ezingaphantsi (umyalelo we-install) | K33: Molo, ndakha i-rpm yeseva yewebhu ye-resin, kwaye ndifuna ukufakela yonke i-tarball phantsi kolawulo lwefolda, kodwa, i-tarball ibandakanya iifolda ezingaphantsi, kwi-spec yam ndine: install -s -m 755 %{name}-%{version}.%{release}/* \ $RPM_BUILD_ROOT/usr/local/resin kwaye ndifumana: install: `resin-2.0.5/bin' is a directory install: `resin-2.0.5/conf' is a directory Ingaba ikho indlela efanelekileyo/entle endifanele ndikusingathe ngayo oku? -- \m/ -- "...ukuba ndibonakala ndingaphezulu komntu ndiye ndingaqondwa kakuhle." (c) Dream Theater mark@talios.com - ICQ: 1934853 JID: talios@myjabber.net _______________________________________________ Uluhlu lwemeyile lwe-RPM-List <RPM-List@freshrpms.net> http://lists.freshrpms.net/mailman/listinfo/rpm-list | L33: http://lists.freshrpms.net/mailman/listinfo/rpm-list
A34: EMAIL_0021 | B34: English | C34: Original | D34: 0 | E34: legitimate | F34: SpamAssassin | G34: zawodny <rssfeeds@spamassassin.taint.org> | H34: yyyy@spamassassin.taint.org | I34: Tue, 01 Oct 2002 08:01:56 -0000 | J34: FreeBSD or Linux for your MySQL Server? | K34: URL: http://jeremy.zawodny.com/blog/archives/000203.html Date: 2002-09-30T17:22:34-08:00 This is an issue that comes up all the time at work. It is an issue for roughly four reasons: Yahoo is a FreeBSD shop Someone has heard that MySQL runs better on Linux Someone knows that we run some... | L34: http://jeremy.zawodny.com/blog/archives/000203.html
A35: EMAIL_0021 | B35: isiZulu | C35: Translation | D35: 0 | E35: legitimate | F35: SpamAssassin | G35: zawodny <rssfeeds@spamassassin.taint.org> | H35: yyyy@spamassassin.taint.org | I35: Tue, 01 Oct 2002 08:01:56 -0000 | J35: I-FreeBSD noma i-Linux yeseva yakho ye-MySQL? | K35: I-URL: http://jeremy.zawodny.com/blog/archives/000203.html Usuku: 2002-09-30T17:22:34-08:00 Lolu wudaba oluvela njalo emsebenzini. Kuyinkinga ngenxa yezizathu ezicishe zibe zine: I-Yahoo isebenzisa i-FreeBSD; kukhona oye wezwa ukuthi i-MySQL isebenza kangcono ku-Linux; kukhona owaziyo ukuthi sisebenzisa... | L35: http://jeremy.zawodny.com/blog/archives/000203.html
